<?xml version="1.0" ?>
<!-- =================================================================================== -->
<!-- |    This document was autogenerated by xacro from robot.xacro                    | -->
<!-- |    EDITING THIS FILE BY HAND IS NOT RECOMMENDED                                 | -->
<!-- =================================================================================== -->
<robot name="g1_description">
  <!-- ros_control plugin -->
  <gazebo>
    <plugin filename="libgazebo_ros_control.so" name="gazebo_ros_control">
      <robotNamespace>/g1_gazebo</robotNamespace>
      <robotSimType>gazebo_ros_control/DefaultRobotHWSim</robotSimType>
    </plugin>
  </gazebo>
  <gazebo reference="imu_link">
    <gravity>true</gravity>
    <sensor name="imu_sensor" type="imu">
      <always_on>true</always_on>
      <update_rate>1000</update_rate>
      <visualize>true</visualize>
      <topic>__default_topic__</topic>
      <plugin filename="libgazebo_ros_imu_sensor.so" name="imu_plugin">
        <topicName>trunk_imu</topicName>
        <bodyName>imu_link</bodyName>
        <updateRateHZ>1000.0</updateRateHZ>
        <gaussianNoise>0.0</gaussianNoise>
        <xyzOffset>0 0 0</xyzOffset>
        <rpyOffset>0 0 0</rpyOffset>
        <frameName>imu_link</frameName>
      </plugin>
      <pose>0 0 0 0 0 0</pose>
    </sensor>
  </gazebo>
  <gazebo reference="base">
    <turnGravityOff>false</turnGravityOff>
  </gazebo>
  <gazebo reference="imu_link">
    <mu1>0.2</mu1>
    <mu2>0.2</mu2>
  </gazebo>
  <!-- Rotor related joint and link is only for demonstrate location. -->
  <!-- Actually, the rotor will rotate and the joint is not fixed. Reduction ratio should be considered. -->
  <!-- Torso -->
  <link name="torso_link">
    <inertial>
      <origin rpy="0 0 0" xyz="0.00197122283 0.00266902037 0.1693651096"/>
      <mass value="6.33959811"/>
      <inertia ixx="0.06037082109027" ixy="-0.00010168407055" ixz="0.00069845018092" iyy="0.04355153796551" iyz="0.00034366422728" izz="0.0333998186601"/>
    </inertial>
    <visual>
      <origin rpy="0 0 0" xyz="0 0 0"/>
      <geometry>
        <mesh filename="package://g1_description/meshes/torso_link.STL"/>
      </geometry>
      <material name="">
        <color rgba="0.7 0.7 0.7 1"/>
      </material>
    </visual>
    <collision>
      <origin rpy="0 0 0" xyz="0.055 0.055 -0.020"/>
      <geometry>
        <sphere radius="0.01"/>
      </geometry>
    </collision>
    <collision>
      <origin rpy="0 0 0" xyz="0.055 -0.055 -0.020"/>
      <geometry>
        <sphere radius="0.01"/>
      </geometry>
    </collision>
    <collision>
      <origin rpy="0 0 0" xyz="-0.055 0.055 -0.020"/>
      <geometry>
        <sphere radius="0.01"/>
      </geometry>
    </collision>
    <collision>
      <origin rpy="0 0 0" xyz="-0.055 -0.055 -0.020"/>
      <geometry>
        <sphere radius="0.01"/>
      </geometry>
    </collision>
    <collision>
      <origin rpy="0 0 0" xyz="0.063 0.088 0.065"/>
      <geometry>
        <sphere radius="0.01"/>
      </geometry>
    </collision>
    <collision>
      <origin rpy="0 0 0" xyz="0.063 -0.088 0.065"/>
      <geometry>
        <sphere radius="0.01"/>
      </geometry>
    </collision>
    <collision>
      <origin rpy="0 0 0" xyz="-0.063 0.088 0.065"/>
      <geometry>
        <sphere radius="0.01"/>
      </geometry>
    </collision>
    <collision>
      <origin rpy="0 0 0" xyz="-0.063 -0.088 0.065"/>
      <geometry>
        <sphere radius="0.01"/>
      </geometry>
    </collision>
    <collision>
      <origin rpy="0 0 0" xyz="0.063 0.088 0.30"/>
      <geometry>
        <sphere radius="0.01"/>
      </geometry>
    </collision>
    <collision>
      <origin rpy="0 0 0" xyz="0.063 -0.088 0.30"/>
      <geometry>
        <sphere radius="0.01"/>
      </geometry>
    </collision>
    <collision>
      <origin rpy="0 0 0" xyz="-0.066 0.088 0.30"/>
      <geometry>
        <sphere radius="0.01"/>
      </geometry>
    </collision>
    <collision>
      <origin rpy="0 0 0" xyz="-0.066 -0.088 0.30"/>
      <geometry>
        <sphere radius="0.01"/>
      </geometry>
    </collision>
  </link>
  <joint name="torso_joint" type="revolute">
    <origin rpy="0 0 0" xyz="0.0 0.0 0.0"/>
    <parent link="pelvis"/>
    <child link="torso_link"/>
    <axis xyz="0 0 1"/>
    <limit effort="88" lower="-2.618" upper="2.618" velocity="32"/>
  </joint>
  <link name="pelvis">
    <inertial>
      <origin rpy="0 0 0" xyz="0 0 -0.07605"/>
      <mass value="2.86"/>
      <inertia ixx="0.0079143" ixy="0" ixz="1.6E-06" iyy="0.0069837" iyz="0" izz="0.0059404"/>
    </inertial>
    <visual>
      <origin rpy="0 0 0" xyz="0 0 0"/>
      <geometry>
        <mesh filename="package://g1_description/meshes/pelvis.STL"/>
      </geometry>
      <material name="">
        <color rgba="0.7 0.7 0.7 1"/>
      </material>
    </visual>
    <collision>
      <origin rpy="0 0 0" xyz="0.050 0.060 -0.060"/>
      <geometry>
        <sphere radius="0.01"/>
      </geometry>
    </collision>
    <collision>
      <origin rpy="0 0 0" xyz="0.050 -0.060 -0.060"/>
      <geometry>
        <sphere radius="0.01"/>
      </geometry>
    </collision>
    <collision>
      <origin rpy="0 0 0" xyz="-0.050 0.060 -0.060"/>
      <geometry>
        <sphere radius="0.01"/>
      </geometry>
    </collision>
    <collision>
      <origin rpy="0 0 0" xyz="-0.050 -0.060 -0.060"/>
      <geometry>
        <sphere radius="0.01"/>
      </geometry>
    </collision>
    <collision>
      <origin rpy="0 0 0" xyz="0.050 0.060 -0.135"/>
      <geometry>
        <sphere radius="0.01"/>
      </geometry>
    </collision>
    <collision>
      <origin rpy="0 0 0" xyz="0.050 -0.060 -0.135"/>
      <geometry>
        <sphere radius="0.01"/>
      </geometry>
    </collision>
    <collision>
      <origin rpy="0 0 0" xyz="-0.050 0.060 -0.135"/>
      <geometry>
        <sphere radius="0.01"/>
      </geometry>
    </collision>
    <collision>
      <origin rpy="0 0 0" xyz="-0.050 -0.060 -0.135"/>
      <geometry>
        <sphere radius="0.01"/>
      </geometry>
    </collision>
  </link>
  <link name="pelvis_contour_link">
    <visual>
      <origin rpy="0 0 0" xyz="0 0 0"/>
      <geometry>
        <mesh filename="package://g1_description/meshes/pelvis_contour_link.STL"/>
      </geometry>
      <material name="">
        <color rgba="0.2 0.2 0.2 1"/>
      </material>
    </visual>
  </link>
  <joint name="pelvis_contour_joint" type="fixed">
    <parent link="pelvis"/>
    <child link="pelvis_contour_link"/>
  </joint>
  <!-- Head -->
  <link name="head_link">
    <inertial>
      <origin rpy="0 0 0" xyz="0.00138066852 0.00028430950 0.42034187824"/>
      <mass value="1.17976522"/>
      <inertia ixx="0.00543236042361" ixy="0.00000140137425" ixz="0.00034554752228" iyy="0.00552885306699" iyz="0.00001501216392" izz="0.00165378108136"/>
    </inertial>
    <visual>
      <origin rpy="0 0 0" xyz="0 0 0"/>
      <geometry>
        <mesh filename="package://g1_description/meshes/head_link.STL"/>
      </geometry>
      <material name="">
        <color rgba="0.2 0.2 0.2 1"/>
      </material>
    </visual>
    <collision>
      <origin rpy="0 0 0" xyz="0.055 0.055 0.48"/>
      <geometry>
        <sphere radius="0.01"/>
      </geometry>
    </collision>
    <collision>
      <origin rpy="0 0 0" xyz="0.055 -0.055 0.48"/>
      <geometry>
        <sphere radius="0.01"/>
      </geometry>
    </collision>
    <collision>
      <origin rpy="0 0 0" xyz="-0.055 0.040 0.48"/>
      <geometry>
        <sphere radius="0.01"/>
      </geometry>
    </collision>
    <collision>
      <origin rpy="0 0 0" xyz="-0.055 -0.040 0.48"/>
      <geometry>
        <sphere radius="0.01"/>
      </geometry>
    </collision>
  </link>
  <joint name="head_joint" type="fixed">
    <origin rpy="0 0 0" xyz="0 0 0"/>
    <parent link="torso_link"/>
    <child link="head_link"/>
  </joint>
  <!-- IMU -->
  <link name="imu_link"/>
  <joint name="imu_joint" type="fixed">
    <origin rpy="0 0 0" xyz="-0.04233868314 0.00166 0.152067"/>
    <parent link="torso_link"/>
    <child link="imu_link"/>
  </joint>
  <!-- checked -->
  <joint name="left_hip_pitch_joint" type="revolute">
    <origin rpy="0 -0.34907 0" xyz="0 0.06445 -0.1027"/>
    <parent link="pelvis"/>
    <child link="left_hip_pitch_link"/>
    <axis xyz="0 1 0"/>
    <limit effort="88" lower="-2.35" upper="3.05" velocity="32"/>
  </joint>
  <!-- Leg -->
  <link name="left_hip_pitch_link">
    <inertial>
      <origin rpy="0 0 0" xyz="0.001962 0.049392 -0.000941"/>
      <mass value="1.299"/>
      <inertia ixx="0.0013873" ixy="-1.63e-05" ixz="-1e-06" iyy="0.0009059" iyz="-4.24e-05" izz="0.0009196"/>
    </inertial>
    <visual>
      <origin rpy="0 0 0" xyz="0 0 0"/>
      <geometry>
        <mesh filename="package://g1_description/meshes/left_hip_pitch_link.STL"/>
      </geometry>
      <material name="">
        <color rgba="0.2 0.2 0.2 1"/>
      </material>
    </visual>
    <collision>
      <origin rpy="0 1.5707 0" xyz="-0.005 0.05 0"/>
      <geometry>
        <cylinder length="0.06" radius="0.05"/>
      </geometry>
    </collision>
  </link>
  <joint name="left_hip_roll_joint" type="revolute">
    <origin rpy="0 0 0" xyz="0 0.0523 0"/>
    <parent link="left_hip_pitch_link"/>
    <child link="left_hip_roll_link"/>
    <axis xyz="1 0 0"/>
    <limit effort="88" lower="-0.26" upper="2.53" velocity="32"/>
  </joint>
  <link name="left_hip_roll_link">
    <inertial>
      <origin rpy="0 0 0" xyz="0.024757 -0.001036 -0.086323"/>
      <mass value="1.446"/>
      <inertia ixx="0.0022702" ixy="-3.7e-06" ixz="-0.0003789" iyy="0.002304" iyz="-1.8e-05" izz="0.0016001"/>
    </inertial>
    <visual>
      <origin rpy="0 0 0" xyz="0 0 0"/>
      <geometry>
        <mesh filename="package://g1_description/meshes/left_hip_roll_link.STL"/>
      </geometry>
      <material name="">
        <color rgba="0.7 0.7 0.7 1"/>
      </material>
    </visual>
    <collision>
      <origin rpy="0 0 0" xyz="0.019 -0.0 -0.11"/>
      <geometry>
        <box size="0.1 0.070 0.02"/>
      </geometry>
    </collision>
  </link>
  <joint name="left_hip_yaw_joint" type="revolute">
    <origin rpy="0 0 0" xyz="0.01966 -0.0012139 -0.1241"/>
    <parent link="left_hip_roll_link"/>
    <child link="left_hip_yaw_link"/>
    <axis xyz="0 0 1"/>
    <limit effort="88" lower="-2.75" upper="2.75" velocity="32"/>
  </joint>
  <link name="left_hip_yaw_link">
    <inertial>
      <origin rpy="0 0 0" xyz="-0.053554 -0.011477 -0.14067"/>
      <mass value="2.052"/>
      <inertia ixx="0.0087264" ixy="-0.0004402" ixz="-0.0036676" iyy="0.011374" iyz="-0.0006654" izz="0.004279"/>
    </inertial>
    <visual>
      <origin rpy="0 0 0" xyz="0 0 0"/>
      <geometry>
        <mesh filename="package://g1_description/meshes/left_hip_yaw_link.STL"/>
      </geometry>
      <material name="">
        <color rgba="0.7 0.7 0.7 1"/>
      </material>
    </visual>
    <collision>
      <origin rpy="1.5707 0 0" xyz="-0.075 0 -0.18"/>
      <geometry>
        <cylinder length="0.06" radius="0.045"/>
      </geometry>
    </collision>
  </link>
  <joint name="left_knee_joint" type="revolute">
    <origin rpy="0 0.5096 0" xyz="-0.078292 -0.0017335 -0.177225"/>
    <parent link="left_hip_yaw_link"/>
    <child link="left_knee_link"/>
    <axis xyz="0 1 0"/>
    <limit effort="139" lower="-0.33489" upper="2.5449" velocity="20"/>
  </joint>
  <link name="left_knee_link">
    <inertial>
      <origin rpy="0 0 0" xyz="0.005505 0.006534 -0.116629"/>
      <mass value="2.252"/>
      <inertia ixx="0.012443837" ixy="5.3496e-05" ixz="-0.000437641" iyy="0.012674902" iyz="-0.000682499" izz="0.001986501"/>
    </inertial>
    <visual>
      <origin rpy="0 0 0" xyz="0 0 0"/>
      <geometry>
        <mesh filename="package://g1_description/meshes/left_knee_link.STL"/>
      </geometry>
      <material name="">
        <color rgba="0.7 0.7 0.7 1"/>
      </material>
    </visual>
    <collision>
      <origin rpy="0 0 0" xyz="0.007 0.005 -0.15"/>
      <geometry>
        <cylinder length="0.15" radius="0.015"/>
      </geometry>
    </collision>
  </link>
  <joint name="left_ankle_pitch_joint" type="revolute">
    <origin rpy="0 -0.16053 0" xyz="0 0.0040687 -0.30007"/>
    <parent link="left_knee_link"/>
    <child link="left_ankle_pitch_link"/>
    <axis xyz="0 1 0"/>
    <limit effort="40" lower="-0.68" upper="0.73" velocity="53"/>
  </joint>
  <link name="left_ankle_pitch_link">
    <inertial>
      <origin rpy="0 0 0" xyz="-0.007269 0 0.011137"/>
      <mass value="0.074"/>
      <inertia ixx="8.4e-06" ixy="0" ixz="-2.9e-06" iyy="1.89e-05" iyz="0" izz="1.26e-05"/>
    </inertial>
    <visual>
      <origin rpy="0 0 0" xyz="0 0 0"/>
      <geometry>
        <mesh filename="package://g1_description/meshes/left_ankle_pitch_link.STL"/>
      </geometry>
      <material name="">
        <color rgba="0.7 0.7 0.7 1"/>
      </material>
    </visual>
  </link>
  <joint name="left_ankle_roll_joint" type="revolute">
    <origin rpy="0 0 0" xyz="0 0 -0.017558"/>
    <parent link="left_ankle_pitch_link"/>
    <child link="left_ankle_roll_link"/>
    <axis xyz="1 0 0"/>
    <limit effort="40" lower="-0.2618" upper="0.2618" velocity="53"/>
  </joint>
  <link name="left_ankle_roll_link">
    <inertial>
      <origin rpy="0 0 0" xyz="0.024762 2e-05 -0.012526"/>
      <mass value="0.391"/>
      <inertia ixx="0.0001552" ixy="-1e-07" ixz="7.51e-05" iyy="0.0010657" iyz="7.51e-05" izz="0.001098"/>
    </inertial>
    <visual>
      <origin rpy="0 0 0" xyz="0 0 0"/>
      <geometry>
        <mesh filename="package://g1_description/meshes/left_ankle_roll_link.STL"/>
      </geometry>
      <material name="">
        <color rgba="0.2 0.2 0.2 1"/>
      </material>
    </visual>
    <!-- <collision>
                <origin xyz="0 0 0" rpy="0 0 0"/>
                <geometry>
                <mesh filename="package://g1_description/meshes/${name}_ankle_roll_link.STL"/>
                </geometry>
            </collision> -->
    <collision>
      <origin rpy="0 0 0" xyz="-0.07 0.03 -0.03"/>
      <geometry>
        <sphere radius="0.003"/>
      </geometry>
    </collision>
    <collision>
      <origin rpy="0 0 0" xyz="-0.07 -0.03 -0.03"/>
      <geometry>
        <sphere radius="0.003"/>
      </geometry>
    </collision>
    <collision>
      <origin rpy="0 0 0" xyz="0.14 0.03 -0.03"/>
      <geometry>
        <sphere radius="0.003"/>
      </geometry>
    </collision>
    <collision>
      <origin rpy="0 0 0" xyz="0.14 -0.03 -0.03"/>
      <geometry>
        <sphere radius="0.003"/>
      </geometry>
    </collision>
    <collision>
      <origin rpy="0 0 0" xyz="-0.060 0.010 0.020"/>
      <geometry>
        <sphere radius="0.003"/>
      </geometry>
    </collision>
    <collision>
      <origin rpy="0 0 0" xyz="-0.060 -0.010 0.020"/>
      <geometry>
        <sphere radius="0.003"/>
      </geometry>
    </collision>
  </link>
  <transmission name="left_hip_pitch_joint_tran">
    <type>transmission_interface/SimpleTransmission</type>
    <joint name="left_hip_pitch_joint">
      <hardwareInterface>hardware_interface/EffortJointInterface</hardwareInterface>
    </joint>
    <actuator name="left_hip_pitch_motor">
      <hardwareInterface>hardware_interface/EffortJointInterface</hardwareInterface>
      <mechanicalReduction>1</mechanicalReduction>
    </actuator>
  </transmission>
  <transmission name="left_hip_roll_joint_tran">
    <type>transmission_interface/SimpleTransmission</type>
    <joint name="left_hip_roll_joint">
      <hardwareInterface>hardware_interface/EffortJointInterface</hardwareInterface>
    </joint>
    <actuator name="left_hip_roll_motor">
      <hardwareInterface>hardware_interface/EffortJointInterface</hardwareInterface>
      <mechanicalReduction>1</mechanicalReduction>
    </actuator>
  </transmission>
  <transmission name="left_hip_yaw_joint_tran">
    <type>transmission_interface/SimpleTransmission</type>
    <joint name="left_hip_yaw_joint">
      <hardwareInterface>hardware_interface/EffortJointInterface</hardwareInterface>
    </joint>
    <actuator name="left_hip_yaw_motor">
      <hardwareInterface>hardware_interface/EffortJointInterface</hardwareInterface>
      <mechanicalReduction>1</mechanicalReduction>
    </actuator>
  </transmission>
  <transmission name="left_knee_joint_tran">
    <type>transmission_interface/SimpleTransmission</type>
    <joint name="left_knee_joint">
      <hardwareInterface>hardware_interface/EffortJointInterface</hardwareInterface>
    </joint>
    <actuator name="left_knee_motor">
      <hardwareInterface>hardware_interface/EffortJointInterface</hardwareInterface>
      <mechanicalReduction>1</mechanicalReduction>
    </actuator>
  </transmission>
  <transmission name="left_ankle_pitch_joint_tran">
    <type>transmission_interface/SimpleTransmission</type>
    <joint name="left_ankle_pitch_joint">
      <hardwareInterface>hardware_interface/EffortJointInterface</hardwareInterface>
    </joint>
    <actuator name="left_ankle_pitch_motor">
      <hardwareInterface>hardware_interface/EffortJointInterface</hardwareInterface>
      <mechanicalReduction>1</mechanicalReduction>
    </actuator>
  </transmission>
  <transmission name="left_ankle_roll_tran">
    <type>transmission_interface/SimpleTransmission</type>
    <joint name="left_ankle_roll_joint">
      <hardwareInterface>hardware_interface/EffortJointInterface</hardwareInterface>
    </joint>
    <actuator name="left_ankle_roll_motor">
      <hardwareInterface>hardware_interface/EffortJointInterface</hardwareInterface>
      <mechanicalReduction>1</mechanicalReduction>
    </actuator>
  </transmission>
  <!-- checked -->
  <joint name="right_hip_pitch_joint" type="revolute">
    <origin rpy="0 -0.34907 0" xyz="0 -0.06445 -0.1027"/>
    <parent link="pelvis"/>
    <child link="right_hip_pitch_link"/>
    <axis xyz="0 1 0"/>
    <limit effort="88" lower="-2.35" upper="3.05" velocity="32"/>
  </joint>
  <!-- Leg -->
  <link name="right_hip_pitch_link">
    <inertial>
      <origin rpy="0 0 0" xyz="0.001962 -0.049392 -0.000941"/>
      <mass value="1.299"/>
      <inertia ixx="0.0013873" ixy="1.63e-05" ixz="-1e-06" iyy="0.0009059" iyz="4.24e-05" izz="0.0009196"/>
    </inertial>
    <visual>
      <origin rpy="0 0 0" xyz="0 0 0"/>
      <geometry>
        <mesh filename="package://g1_description/meshes/right_hip_pitch_link.STL"/>
      </geometry>
      <material name="">
        <color rgba="0.2 0.2 0.2 1"/>
      </material>
    </visual>
    <collision>
      <origin rpy="0 1.5707 0" xyz="-0.005 -0.05 0"/>
      <geometry>
        <cylinder length="0.06" radius="0.05"/>
      </geometry>
    </collision>
  </link>
  <joint name="right_hip_roll_joint" type="revolute">
    <origin rpy="0 0 0" xyz="0 -0.0523 0"/>
    <parent link="right_hip_pitch_link"/>
    <child link="right_hip_roll_link"/>
    <axis xyz="1 0 0"/>
    <limit effort="88" lower="-2.53" upper="0.26" velocity="32"/>
  </joint>
  <link name="right_hip_roll_link">
    <inertial>
      <origin rpy="0 0 0" xyz="0.024757 0.001036 -0.086323"/>
      <mass value="1.446"/>
      <inertia ixx="0.0022702" ixy="3.7e-06" ixz="-0.0003789" iyy="0.002304" iyz="1.8e-05" izz="0.0016001"/>
    </inertial>
    <visual>
      <origin rpy="0 0 0" xyz="0 0 0"/>
      <geometry>
        <mesh filename="package://g1_description/meshes/right_hip_roll_link.STL"/>
      </geometry>
      <material name="">
        <color rgba="0.7 0.7 0.7 1"/>
      </material>
    </visual>
    <collision>
      <origin rpy="0 0 0" xyz="0.019 -0.0 -0.11"/>
      <geometry>
        <box size="0.1 0.070 0.02"/>
      </geometry>
    </collision>
  </link>
  <joint name="right_hip_yaw_joint" type="revolute">
    <origin rpy="0 0 0" xyz="0.01966 0.0012139 -0.1241"/>
    <parent link="right_hip_roll_link"/>
    <child link="right_hip_yaw_link"/>
    <axis xyz="0 0 1"/>
    <limit effort="88" lower="-2.75" upper="2.75" velocity="32"/>
  </joint>
  <link name="right_hip_yaw_link">
    <inertial>
      <origin rpy="0 0 0" xyz="-0.053554 0.011477 -0.14067"/>
      <mass value="2.052"/>
      <inertia ixx="0.0087264" ixy="0.0004402" ixz="-0.0036676" iyy="0.011374" iyz="0.0006654" izz="0.004279"/>
    </inertial>
    <visual>
      <origin rpy="0 0 0" xyz="0 0 0"/>
      <geometry>
        <mesh filename="package://g1_description/meshes/right_hip_yaw_link.STL"/>
      </geometry>
      <material name="">
        <color rgba="0.7 0.7 0.7 1"/>
      </material>
    </visual>
    <collision>
      <origin rpy="1.5707 0 0" xyz="-0.075 0 -0.18"/>
      <geometry>
        <cylinder length="0.06" radius="0.045"/>
      </geometry>
    </collision>
  </link>
  <joint name="right_knee_joint" type="revolute">
    <origin rpy="0 0.5096 0" xyz="-0.078292 0.0017335 -0.177225"/>
    <parent link="right_hip_yaw_link"/>
    <child link="right_knee_link"/>
    <axis xyz="0 1 0"/>
    <limit effort="139" lower="-0.33489" upper="2.5449" velocity="20"/>
  </joint>
  <link name="right_knee_link">
    <inertial>
      <origin rpy="0 0 0" xyz="0.005505 -0.006534 -0.116629"/>
      <mass value="2.252"/>
      <inertia ixx="0.012443837" ixy="-5.3496e-05" ixz="-0.000437641" iyy="0.012674902" iyz="0.000682499" izz="0.001986501"/>
    </inertial>
    <visual>
      <origin rpy="0 0 0" xyz="0 0 0"/>
      <geometry>
        <mesh filename="package://g1_description/meshes/right_knee_link.STL"/>
      </geometry>
      <material name="">
        <color rgba="0.7 0.7 0.7 1"/>
      </material>
    </visual>
    <collision>
      <origin rpy="0 0 0" xyz="0.007 -0.005 -0.15"/>
      <geometry>
        <cylinder length="0.15" radius="0.015"/>
      </geometry>
    </collision>
  </link>
  <joint name="right_ankle_pitch_joint" type="revolute">
    <origin rpy="0 -0.16053 0" xyz="0 -0.0040687 -0.30007"/>
    <parent link="right_knee_link"/>
    <child link="right_ankle_pitch_link"/>
    <axis xyz="0 1 0"/>
    <limit effort="40" lower="-0.68" upper="0.73" velocity="53"/>
  </joint>
  <link name="right_ankle_pitch_link">
    <inertial>
      <origin rpy="0 0 0" xyz="-0.007269 0 0.011137"/>
      <mass value="0.074"/>
      <inertia ixx="8.4e-06" ixy="0" ixz="-2.9e-06" iyy="1.89e-05" iyz="0" izz="1.26e-05"/>
    </inertial>
    <visual>
      <origin rpy="0 0 0" xyz="0 0 0"/>
      <geometry>
        <mesh filename="package://g1_description/meshes/right_ankle_pitch_link.STL"/>
      </geometry>
      <material name="">
        <color rgba="0.7 0.7 0.7 1"/>
      </material>
    </visual>
  </link>
  <joint name="right_ankle_roll_joint" type="revolute">
    <origin rpy="0 0 0" xyz="0 0 -0.017558"/>
    <parent link="right_ankle_pitch_link"/>
    <child link="right_ankle_roll_link"/>
    <axis xyz="1 0 0"/>
    <limit effort="40" lower="-0.2618" upper="0.2618" velocity="53"/>
  </joint>
  <link name="right_ankle_roll_link">
    <inertial>
      <origin rpy="0 0 0" xyz="0.024762 -2e-05 -0.012526"/>
      <mass value="0.391"/>
      <inertia ixx="0.0001552" ixy="1e-07" ixz="7.51e-05" iyy="0.0010657" iyz="-7.51e-05" izz="0.001098"/>
    </inertial>
    <visual>
      <origin rpy="0 0 0" xyz="0 0 0"/>
      <geometry>
        <mesh filename="package://g1_description/meshes/right_ankle_roll_link.STL"/>
      </geometry>
      <material name="">
        <color rgba="0.2 0.2 0.2 1"/>
      </material>
    </visual>
    <!-- <collision>
                <origin xyz="0 0 0" rpy="0 0 0"/>
                <geometry>
                <mesh filename="package://g1_description/meshes/${name}_ankle_roll_link.STL"/>
                </geometry>
            </collision> -->
    <collision>
      <origin rpy="0 0 0" xyz="-0.07 0.03 -0.03"/>
      <geometry>
        <sphere radius="0.003"/>
      </geometry>
    </collision>
    <collision>
      <origin rpy="0 0 0" xyz="-0.07 -0.03 -0.03"/>
      <geometry>
        <sphere radius="0.003"/>
      </geometry>
    </collision>
    <collision>
      <origin rpy="0 0 0" xyz="0.14 0.03 -0.03"/>
      <geometry>
        <sphere radius="0.003"/>
      </geometry>
    </collision>
    <collision>
      <origin rpy="0 0 0" xyz="0.14 -0.03 -0.03"/>
      <geometry>
        <sphere radius="0.003"/>
      </geometry>
    </collision>
    <collision>
      <origin rpy="0 0 0" xyz="-0.060 0.010 0.020"/>
      <geometry>
        <sphere radius="0.003"/>
      </geometry>
    </collision>
    <collision>
      <origin rpy="0 0 0" xyz="-0.060 -0.010 0.020"/>
      <geometry>
        <sphere radius="0.003"/>
      </geometry>
    </collision>
  </link>
  <transmission name="right_hip_pitch_joint_tran">
    <type>transmission_interface/SimpleTransmission</type>
    <joint name="right_hip_pitch_joint">
      <hardwareInterface>hardware_interface/EffortJointInterface</hardwareInterface>
    </joint>
    <actuator name="right_hip_pitch_motor">
      <hardwareInterface>hardware_interface/EffortJointInterface</hardwareInterface>
      <mechanicalReduction>1</mechanicalReduction>
    </actuator>
  </transmission>
  <transmission name="right_hip_roll_joint_tran">
    <type>transmission_interface/SimpleTransmission</type>
    <joint name="right_hip_roll_joint">
      <hardwareInterface>hardware_interface/EffortJointInterface</hardwareInterface>
    </joint>
    <actuator name="right_hip_roll_motor">
      <hardwareInterface>hardware_interface/EffortJointInterface</hardwareInterface>
      <mechanicalReduction>1</mechanicalReduction>
    </actuator>
  </transmission>
  <transmission name="right_hip_yaw_joint_tran">
    <type>transmission_interface/SimpleTransmission</type>
    <joint name="right_hip_yaw_joint">
      <hardwareInterface>hardware_interface/EffortJointInterface</hardwareInterface>
    </joint>
    <actuator name="right_hip_yaw_motor">
      <hardwareInterface>hardware_interface/EffortJointInterface</hardwareInterface>
      <mechanicalReduction>1</mechanicalReduction>
    </actuator>
  </transmission>
  <transmission name="right_knee_joint_tran">
    <type>transmission_interface/SimpleTransmission</type>
    <joint name="right_knee_joint">
      <hardwareInterface>hardware_interface/EffortJointInterface</hardwareInterface>
    </joint>
    <actuator name="right_knee_motor">
      <hardwareInterface>hardware_interface/EffortJointInterface</hardwareInterface>
      <mechanicalReduction>1</mechanicalReduction>
    </actuator>
  </transmission>
  <transmission name="right_ankle_pitch_joint_tran">
    <type>transmission_interface/SimpleTransmission</type>
    <joint name="right_ankle_pitch_joint">
      <hardwareInterface>hardware_interface/EffortJointInterface</hardwareInterface>
    </joint>
    <actuator name="right_ankle_pitch_motor">
      <hardwareInterface>hardware_interface/EffortJointInterface</hardwareInterface>
      <mechanicalReduction>1</mechanicalReduction>
    </actuator>
  </transmission>
  <transmission name="right_ankle_roll_tran">
    <type>transmission_interface/SimpleTransmission</type>
    <joint name="right_ankle_roll_joint">
      <hardwareInterface>hardware_interface/EffortJointInterface</hardwareInterface>
    </joint>
    <actuator name="right_ankle_roll_motor">
      <hardwareInterface>hardware_interface/EffortJointInterface</hardwareInterface>
      <mechanicalReduction>1</mechanicalReduction>
    </actuator>
  </transmission>
  <joint name="left_shoulder_pitch_joint" type="revolute">
    <origin rpy="0.27925 0 0" xyz="-0.0025 0.10396 0.25928"/>
    <parent link="torso_link"/>
    <child link="left_shoulder_pitch_link"/>
    <axis xyz="0 1 0"/>
    <limit effort="21" lower="-2.9671" upper="2.7925" velocity="53"/>
  </joint>
  <link name="left_shoulder_pitch_link">
    <inertial>
      <origin rpy="0 0 0" xyz="-0.001431 0.048811 0.001304"/>
      <mass value="0.713"/>
      <inertia ixx="0.0004614" ixy="-9.3e-06" ixz="1e-05" iyy="0.0004146" iyz="5.5e-06" izz="0.0004416"/>
    </inertial>
    <visual>
      <origin rpy="0 0 0" xyz="0 0 0"/>
      <geometry>
        <mesh filename="package://g1_description/meshes/left_shoulder_pitch_link.STL"/>
      </geometry>
      <material name="">
        <color rgba="0.7 0.7 0.7 1"/>
      </material>
    </visual>
    <collision>
      <origin rpy="0 1.5707 0" xyz="0 0.06 0"/>
      <geometry>
        <cylinder length="0.065" radius="0.03"/>
      </geometry>
    </collision>
  </link>
  <joint name="left_shoulder_roll_joint" type="revolute">
    <origin rpy="-0.27925 0 0" xyz="0 0.052 0"/>
    <parent link="left_shoulder_pitch_link"/>
    <child link="left_shoulder_roll_link"/>
    <axis xyz="1 0 0"/>
    <limit effort="21" lower="-1.5882" upper="2.2515" velocity="53"/>
    <limit effort="21" lower="-1.5882" upper="2.2515" velocity="53"/>
  </joint>
  <link name="left_shoulder_roll_link">
    <inertial>
      <origin rpy="0 0 0" xyz="-0.003415 0.006955 -0.064598"/>
      <mass value="0.642"/>
      <inertia ixx="0.0006159" ixy="0" ixz="-5.6e-06" iyy="0.0006835" iyz="2.1e-06" izz="0.000373"/>
    </inertial>
    <visual>
      <origin rpy="0 0 0" xyz="0 0 0"/>
      <geometry>
        <mesh filename="package://g1_description/meshes/left_shoulder_roll_link.STL"/>
      </geometry>
      <material name="">
        <color rgba="0.7 0.7 0.7 1"/>
      </material>
    </visual>
    <collision>
      <origin rpy="0 0 0" xyz="-0.005 0.01 -0.080"/>
      <geometry>
        <cylinder length="0.03" radius="0.03"/>
      </geometry>
    </collision>
  </link>
  <joint name="left_shoulder_yaw_joint" type="revolute">
    <origin rpy="0 0 0" xyz="-0.00354 0.0062424 -0.1032"/>
    <parent link="left_shoulder_roll_link"/>
    <child link="left_shoulder_yaw_link"/>
    <axis xyz="0 0 1"/>
    <limit effort="21" lower="-2.618" upper="2.618" velocity="53"/>
  </joint>
  <link name="left_shoulder_yaw_link">
    <inertial>
      <origin rpy="0 0 0" xyz="0.000375 -0.00444 -0.072374"/>
      <mass value="0.713"/>
      <inertia ixx="0.0009699" ixy="7.1e-06" ixz="7.8e-06" iyy="0.0009691" iyz="-4.49e-05" izz="0.0003826"/>
    </inertial>
    <visual>
      <origin rpy="0 0 0" xyz="0 0 0"/>
      <geometry>
        <mesh filename="package://g1_description/meshes/left_shoulder_yaw_link.STL"/>
      </geometry>
      <material name="">
        <color rgba="0.7 0.7 0.7 1"/>
      </material>
    </visual>
    <collision>
      <origin rpy="0 0 0" xyz="-0.0 -0.0 -0.05"/>
      <geometry>
        <cylinder length="0.03" radius="0.03"/>
      </geometry>
    </collision>
  </link>
  <joint name="left_elbow_pitch_joint" type="revolute">
    <origin rpy="0 0 0" xyz="0 0.00189 -0.0855"/>
    <parent link="left_shoulder_yaw_link"/>
    <child link="left_elbow_pitch_link"/>
    <axis xyz="0 1 0"/>
    <limit effort="21" lower="-0.2268" upper="3.4208" velocity="53"/>
  </joint>
  <link name="left_elbow_pitch_link">
    <inertial>
      <origin rpy="0 0 0" xyz="0.064497 0.002873 0"/>
      <mass value="0.601"/>
      <inertia ixx="0.0002845" ixy="8.06e-05" ixz="9e-09" iyy="0.0004647" iyz="5e-09" izz="0.0004712"/>
    </inertial>
    <visual>
      <origin rpy="0 0 0" xyz="0 0 0"/>
      <geometry>
        <mesh filename="package://g1_description/meshes/left_elbow_pitch_link.STL"/>
      </geometry>
      <material name="">
        <color rgba="0.7 0.7 0.7 1"/>
      </material>
    </visual>
    <collision>
      <origin rpy="0 1.5707 0" xyz="0.07 -0.0 -0.0"/>
      <geometry>
        <cylinder length="0.03" radius="0.03"/>
      </geometry>
    </collision>
  </link>
  <joint name="left_elbow_roll_joint" type="revolute">
    <origin rpy="0 0 0" xyz="0.1 0 0"/>
    <parent link="left_elbow_pitch_link"/>
    <child link="left_elbow_roll_link"/>
    <axis xyz="1 0 0"/>
    <limit effort="21" lower="-2.0943" upper="2.0943" velocity="53"/>
  </joint>
  <link name="left_elbow_roll_link">
    <inertial>
      <origin rpy="0 0 0" xyz="0.081811 0.001454 0.001"/>
      <mass value="0.227"/>
      <inertia ixx="0.0001093" ixy="-1.55e-05" ixz="-2.91e-05" iyy="0.000977" iyz="1e-06" izz="0.0009676"/>
    </inertial>
    <visual>
      <origin rpy="0 0 0" xyz="0 0 0"/>
      <geometry>
        <mesh filename="package://g1_description/meshes/left_elbow_roll_link.STL"/>
      </geometry>
      <material name="">
        <color rgba="0.7 0.7 0.7 1"/>
      </material>
    </visual>
    <collision>
      <origin rpy="0 1.5707 0" xyz="0.09 0.005 -0.0"/>
      <geometry>
        <cylinder length="0.03" radius="0.025"/>
      </geometry>
    </collision>
  </link>
  <transmission name="left_shoulder_pitch_joint_tran">
    <type>transmission_interface/SimpleTransmission</type>
    <joint name="left_shoulder_pitch_joint">
      <hardwareInterface>hardware_interface/EffortJointInterface</hardwareInterface>
    </joint>
    <actuator name="left_shoulder_pitch_motor">
      <hardwareInterface>hardware_interface/EffortJointInterface</hardwareInterface>
      <mechanicalReduction>1</mechanicalReduction>
    </actuator>
  </transmission>
  <transmission name="left_shoulder_roll_joint_tran">
    <type>transmission_interface/SimpleTransmission</type>
    <joint name="left_shoulder_roll_joint">
      <hardwareInterface>hardware_interface/EffortJointInterface</hardwareInterface>
    </joint>
    <actuator name="left_shoulder_roll_motor">
      <hardwareInterface>hardware_interface/EffortJointInterface</hardwareInterface>
      <mechanicalReduction>1</mechanicalReduction>
    </actuator>
  </transmission>
  <transmission name="left_shoulder_yaw_joint_tran">
    <type>transmission_interface/SimpleTransmission</type>
    <joint name="left_shoulder_yaw_joint">
      <hardwareInterface>hardware_interface/EffortJointInterface</hardwareInterface>
    </joint>
    <actuator name="left_shoulder_yaw_motor">
      <hardwareInterface>hardware_interface/EffortJointInterface</hardwareInterface>
      <mechanicalReduction>1</mechanicalReduction>
    </actuator>
  </transmission>
  <transmission name="left_elbow_pitch_joint_tran">
    <type>transmission_interface/SimpleTransmission</type>
    <joint name="left_elbow_pitch_joint">
      <hardwareInterface>hardware_interface/EffortJointInterface</hardwareInterface>
    </joint>
    <actuator name="left_elbow_pitch_motor">
      <hardwareInterface>hardware_interface/EffortJointInterface</hardwareInterface>
      <mechanicalReduction>1</mechanicalReduction>
    </actuator>
  </transmission>
  <transmission name="left_elbow_roll_joint_tran">
    <type>transmission_interface/SimpleTransmission</type>
    <joint name="left_elbow_roll_joint">
      <hardwareInterface>hardware_interface/EffortJointInterface</hardwareInterface>
    </joint>
    <actuator name="left_elbow_roll_motor">
      <hardwareInterface>hardware_interface/EffortJointInterface</hardwareInterface>
      <mechanicalReduction>1</mechanicalReduction>
    </actuator>
  </transmission>
  <joint name="right_shoulder_pitch_joint" type="revolute">
    <origin rpy="-0.27925 0 0" xyz="-0.0025 -0.10396 0.25928"/>
    <parent link="torso_link"/>
    <child link="right_shoulder_pitch_link"/>
    <axis xyz="0 1 0"/>
    <limit effort="21" lower="-2.9671" upper="2.7925" velocity="53"/>
  </joint>
  <link name="right_shoulder_pitch_link">
    <inertial>
      <origin rpy="0 0 0" xyz="-0.001431 -0.048811 0.001304"/>
      <mass value="0.713"/>
      <inertia ixx="0.0004614" ixy="9.3e-06" ixz="1e-05" iyy="0.0004146" iyz="-5.5e-06" izz="0.0004416"/>
    </inertial>
    <visual>
      <origin rpy="0 0 0" xyz="0 0 0"/>
      <geometry>
        <mesh filename="package://g1_description/meshes/right_shoulder_pitch_link.STL"/>
      </geometry>
      <material name="">
        <color rgba="0.7 0.7 0.7 1"/>
      </material>
    </visual>
    <collision>
      <origin rpy="0 1.5707 0" xyz="0 -0.06 0"/>
      <geometry>
        <cylinder length="0.065" radius="0.03"/>
      </geometry>
    </collision>
  </link>
  <joint name="right_shoulder_roll_joint" type="revolute">
    <origin rpy="0.27925 0 0" xyz="0 -0.052 0"/>
    <parent link="right_shoulder_pitch_link"/>
    <child link="right_shoulder_roll_link"/>
    <axis xyz="1 0 0"/>
    <limit effort="21" lower="-1.5882" upper="2.2515" velocity="53"/>
    <limit effort="21" lower="-2.2515" upper="1.5882" velocity="53"/>
  </joint>
  <link name="right_shoulder_roll_link">
    <inertial>
      <origin rpy="0 0 0" xyz="-0.003415 -0.006955 -0.064598"/>
      <mass value="0.642"/>
      <inertia ixx="0.0006159" ixy="0" ixz="-5.6e-06" iyy="0.0006835" iyz="-2.1e-06" izz="0.000373"/>
    </inertial>
    <visual>
      <origin rpy="0 0 0" xyz="0 0 0"/>
      <geometry>
        <mesh filename="package://g1_description/meshes/right_shoulder_roll_link.STL"/>
      </geometry>
      <material name="">
        <color rgba="0.7 0.7 0.7 1"/>
      </material>
    </visual>
    <collision>
      <origin rpy="0 0 0" xyz="-0.005 -0.01 -0.080"/>
      <geometry>
        <cylinder length="0.03" radius="0.03"/>
      </geometry>
    </collision>
  </link>
  <joint name="right_shoulder_yaw_joint" type="revolute">
    <origin rpy="0 0 0" xyz="-0.00354 -0.0062424 -0.1032"/>
    <parent link="right_shoulder_roll_link"/>
    <child link="right_shoulder_yaw_link"/>
    <axis xyz="0 0 1"/>
    <limit effort="21" lower="-2.618" upper="2.618" velocity="53"/>
  </joint>
  <link name="right_shoulder_yaw_link">
    <inertial>
      <origin rpy="0 0 0" xyz="0.000375 0.00444 -0.072374"/>
      <mass value="0.713"/>
      <inertia ixx="0.0009699" ixy="-7.1e-06" ixz="7.8e-06" iyy="0.0009691" iyz="4.49e-05" izz="0.0003826"/>
    </inertial>
    <visual>
      <origin rpy="0 0 0" xyz="0 0 0"/>
      <geometry>
        <mesh filename="package://g1_description/meshes/right_shoulder_yaw_link.STL"/>
      </geometry>
      <material name="">
        <color rgba="0.7 0.7 0.7 1"/>
      </material>
    </visual>
    <collision>
      <origin rpy="0 0 0" xyz="-0.0 -0.0 -0.05"/>
      <geometry>
        <cylinder length="0.03" radius="0.03"/>
      </geometry>
    </collision>
  </link>
  <joint name="right_elbow_pitch_joint" type="revolute">
    <origin rpy="0 0 0" xyz="0 -0.00189 -0.0855"/>
    <parent link="right_shoulder_yaw_link"/>
    <child link="right_elbow_pitch_link"/>
    <axis xyz="0 1 0"/>
    <limit effort="21" lower="-0.2268" upper="3.4208" velocity="53"/>
  </joint>
  <link name="right_elbow_pitch_link">
    <inertial>
      <origin rpy="0 0 0" xyz="0.064497 -0.002873 0"/>
      <mass value="0.601"/>
      <inertia ixx="0.0002845" ixy="-8.06e-05" ixz="9e-09" iyy="0.0004647" iyz="-5e-09" izz="0.0004712"/>
    </inertial>
    <visual>
      <origin rpy="0 0 0" xyz="0 0 0"/>
      <geometry>
        <mesh filename="package://g1_description/meshes/right_elbow_pitch_link.STL"/>
      </geometry>
      <material name="">
        <color rgba="0.7 0.7 0.7 1"/>
      </material>
    </visual>
    <collision>
      <origin rpy="0 1.5707 0" xyz="0.07 -0.0 -0.0"/>
      <geometry>
        <cylinder length="0.03" radius="0.03"/>
      </geometry>
    </collision>
  </link>
  <joint name="right_elbow_roll_joint" type="revolute">
    <origin rpy="0 0 0" xyz="0.1 0 0"/>
    <parent link="right_elbow_pitch_link"/>
    <child link="right_elbow_roll_link"/>
    <axis xyz="1 0 0"/>
    <limit effort="21" lower="-2.0943" upper="2.0943" velocity="53"/>
  </joint>
  <link name="right_elbow_roll_link">
    <inertial>
      <origin rpy="0 0 0" xyz="0.081811 -0.001454 0.001"/>
      <mass value="0.227"/>
      <inertia ixx="0.0001093" ixy="1.55e-05" ixz="-2.91e-05" iyy="0.000977" iyz="-1e-06" izz="0.0009676"/>
    </inertial>
    <visual>
      <origin rpy="0 0 0" xyz="0 0 0"/>
      <geometry>
        <mesh filename="package://g1_description/meshes/right_elbow_roll_link.STL"/>
      </geometry>
      <material name="">
        <color rgba="0.7 0.7 0.7 1"/>
      </material>
    </visual>
    <collision>
      <origin rpy="0 1.5707 0" xyz="0.09 0.005 -0.0"/>
      <geometry>
        <cylinder length="0.03" radius="0.025"/>
      </geometry>
    </collision>
  </link>
  <transmission name="right_shoulder_pitch_joint_tran">
    <type>transmission_interface/SimpleTransmission</type>
    <joint name="right_shoulder_pitch_joint">
      <hardwareInterface>hardware_interface/EffortJointInterface</hardwareInterface>
    </joint>
    <actuator name="right_shoulder_pitch_motor">
      <hardwareInterface>hardware_interface/EffortJointInterface</hardwareInterface>
      <mechanicalReduction>1</mechanicalReduction>
    </actuator>
  </transmission>
  <transmission name="right_shoulder_roll_joint_tran">
    <type>transmission_interface/SimpleTransmission</type>
    <joint name="right_shoulder_roll_joint">
      <hardwareInterface>hardware_interface/EffortJointInterface</hardwareInterface>
    </joint>
    <actuator name="right_shoulder_roll_motor">
      <hardwareInterface>hardware_interface/EffortJointInterface</hardwareInterface>
      <mechanicalReduction>1</mechanicalReduction>
    </actuator>
  </transmission>
  <transmission name="right_shoulder_yaw_joint_tran">
    <type>transmission_interface/SimpleTransmission</type>
    <joint name="right_shoulder_yaw_joint">
      <hardwareInterface>hardware_interface/EffortJointInterface</hardwareInterface>
    </joint>
    <actuator name="right_shoulder_yaw_motor">
      <hardwareInterface>hardware_interface/EffortJointInterface</hardwareInterface>
      <mechanicalReduction>1</mechanicalReduction>
    </actuator>
  </transmission>
  <transmission name="right_elbow_pitch_joint_tran">
    <type>transmission_interface/SimpleTransmission</type>
    <joint name="right_elbow_pitch_joint">
      <hardwareInterface>hardware_interface/EffortJointInterface</hardwareInterface>
    </joint>
    <actuator name="right_elbow_pitch_motor">
      <hardwareInterface>hardware_interface/EffortJointInterface</hardwareInterface>
      <mechanicalReduction>1</mechanicalReduction>
    </actuator>
  </transmission>
  <transmission name="right_elbow_roll_joint_tran">
    <type>transmission_interface/SimpleTransmission</type>
    <joint name="right_elbow_roll_joint">
      <hardwareInterface>hardware_interface/EffortJointInterface</hardwareInterface>
    </joint>
    <actuator name="right_elbow_roll_motor">
      <hardwareInterface>hardware_interface/EffortJointInterface</hardwareInterface>
      <mechanicalReduction>1</mechanicalReduction>
    </actuator>
  </transmission>
  <transmission name="torso_tran">
    <type>transmission_interface/SimpleTransmission</type>
    <joint name="torso_joint">
      <hardwareInterface>hardware_interface/EffortJointInterface</hardwareInterface>
    </joint>
    <actuator name="torso_motor">
      <hardwareInterface>hardware_interface/EffortJointInterface</hardwareInterface>
      <mechanicalReduction>1</mechanicalReduction>
    </actuator>
  </transmission>
</robot>

